Workbook

Sheet Lisez-moi
A1: Fichier de prospection YEBA FORMATIONS – 974 (5 octobre 2026)
A3: Comment l'utiliser
A4: • Cellules jaunes = à remplir (Statut, Date 1er contact, Notes). Exemple : Statut « Contacté », date 06/10/2026, note « standard : rappeler M. X jeudi ».
A5: • Filtrez par Priorité (1 = cibles les plus mûres : comptables, courtiers, immobilier, notaires, avocats) puis appelez le standard.
A6: • L'onglet « Synthèse » se met à jour seul.
A8: D'où viennent les données
A9: • Uniquement d'annuaires et de sites publics consultés le 05/10/2026 (colonne Source). Rien n'est inventé : une case vide = information non trouvée.
A10: • Vérifiez chaque numéro avant d'appeler (les annuaires ne sont pas toujours à jour). Complétez l'email depuis la page contact du site.
A11: • Pour une liste exhaustive (des milliers d'entreprises, avec SIREN et effectif) : lancez prospection/extraire_entreprises_974.py depuis votre ordinateur (API publique de l'État, bloquée sur mon serveur).
A13: RGPD (à respecter)
A14: • Seules des entreprises figurent ici : les entrepreneurs individuels et les noms de personnes ont été écartés (minimisation, art. 5 RGPD).
A15: • Email B2B : autorisé sans consentement si l'offre concerne la fonction du destinataire. Indiquez votre identité, la source des coordonnées et un moyen de s'opposer (art. 14 et 21 RGPD).
... A22: • OPCO « probable » : déduit de la convention collective habituelle du secteur ; à confirmer avec l'entreprise.

Sheet Prospects 974
A1: N° | B1: Entreprise | C1: Secteur | D1: Priorité | E1: Commune | F1: Adresse | G1: Téléphone standard | H1: Email générique | I1: Site web | J1: OPCO probable | K1: Accroche suggérée | L1: Statut | M1: Date 1er contact | N1: Notes | O1: Source | P1: Remarque vérifiée
A2: 1 | B2: Cabinet d'Avocats Nativel | C2: Cabinets d'avocats | D2: 1 | E2: Saint-Denis | F2: 3 rue Cité Jasmin ou 20 rue Saint-Jacques, 97400 (sources divergentes) ; bureau secondaire à Saint-Pierre | J2: OPCO EP | K2: Secret professionnel + IA générative : charte, outils souverains, formation des collaborateurs (OPCO EP). | L2: À qualifier | O2: https://www.annuaireavocats.fr/cabinets/droit-des-affaires/saint-denis-la-reunion ; https://gery-avocats-associes.fr/ | P2: Adresse à confirmer
A3: 2 | B3: Gery Avocats Associés | C3: Cabinets d'avocats | D3: 1 | E3: Saint-Denis | F3: 12 rue Labourdonnais, 97400 | I3: https://gery-avocats-associes.fr/ | J3: OPCO EP | K3: Secret professionnel + IA générative : charte, outils souverains, formation des collaborateurs (OPCO EP). | L3: À qualifier | O3: https://www.annuaireavocats.fr/cabinets/droit-des-affaires/saint-denis-la-reunion ; https://gery-avocats-associes.fr/
A4: 3 | B4: OCRE Avocats | C4: Cabinets d'avocats | D4: 1 | E4: Saint-Denis | F4: 74 rue Monthyon, 97400 | J4: OPCO EP | K4: Secret professionnel + IA générative : charte, outils souverains, formation des collaborateurs (OPCO EP). | L4: À qualifier | O4: https://www.annuaireavocats.fr/cabinets/droit-des-affaires/saint-denis-la-reunion ; https://gery-avocats-associes.fr/
A5: 4 | B5: Rivière – Delrieu & Associés | C5: Cabinets d'avocats | D5: 1 | E5: Saint-Denis | J5: OPCO EP | K5: Secret professionnel + IA générative : charte, outils souverains, formation des collaborateurs (OPCO EP). | L5: À qualifier | O5: https://www.annuaireavocats.fr/cabinets/droit-des-affaires/saint-denis-la-reunion ; https://gery-avocats-associes.fr/
A6: 5 | B6: Assurance Réunion Solutions | C6: Courtage & assurance | D6: 1 | E6: Saint-Denis | F6: Bât. Jardin de Juliette, 139 rue Juliette Dodu, 97400 | G6: 02 62 31 97 87 | J6: Atlas | K6: Données sensibles des assurés : usage maîtrisé de l'IA, RGPD et preuve de mesures art. 4 (OPCO Atlas). | L6: À qualifier | O6: https://www.pagesjaunes.fr/annuaire/saint-denis-974/assurances-courtiers ; https://www.assurco-assurance-reunion.fr/ ; https://www.courtierassurances.re/ ; https://www.cea-assurances.fr/nos-agences/agence-reunion/
A7: 6 | B7: Assurco | C7: Courtage & assurance | D7: 1 | E7: Saint-Denis | F7: 13 rue Charles Gounod, 97400 | G7: 02 62 94 13 65 | H7: direction@assurco.re | I7: https://www.assurco-assurance-reunion.fr/ | J7: Atlas | K7: Données sensibles des assurés : usage maîtrisé de l'IA, RGPD et preuve de mesures art. 4 (OPCO Atlas). | L7: À qualifier | O7: Recherche web 05/10/2026 (email direction@assurco.re cité avec le téléphone 0262941365) ; https://www.assurco-assurance-reunion.fr/ | P7: 4 agences sur l'île
A8: 7 | B8: CEA Réunion – Centre d'études d'assurances | C8: Courtage & assurance | D8: 1 | E8: Saint-Denis | F8: 98 rue Jules Auber, 97400 | I8: https://www.cea-assurances.fr/nos-agences/agence-reunion/ | J8: Atlas | K8: Données sensibles des assurés : usage maîtrisé de l'IA, RGPD et preuve de mesures art. 4 (OPCO Atlas). | L8: À qualifier | O8: https://www.pappers.fr/entreprise/439031857 ; https://www.cea-assurances.fr/nos-agences/agence-reunion/
A9: 8 | B9: Courtier Assurances | C9: Courtage & assurance | D9: 1 | E9: Saint-Denis | F9: 10 rue de Nice, 97400 | G9: 02 62 46 04 46 | I9: https://www.courtierassurances.re/ | J9: Atlas | K9: Données sensibles des assurés : usage maîtrisé de l'IA, RGPD et preuve de mesures art. 4 (OPCO Atlas). | L9: À qualifier | O9: https://www.pagesjaunes.fr/annuaire/saint-denis-974/assurances-courtiers ; https://www.assurco-assurance-reunion.fr/ ; https://www.courtierassurances.re/ ; https://www.cea-assurances.fr/nos-agences/agence-reunion/
A10: 9 | B10: Isautier Assurances | C10: Courtage & assurance | D10: 1 | E10: Saint-Denis | F10: 15 rue Juliette Dodu, 97400 | G10: 02 62 90 19 19 | J10: Atlas | K10: Données sensibles des assurés : usage maîtrisé de l'IA, RGPD et preuve de mesures art. 4 (OPCO Atlas). | L10: À qualifier | O10: https://www.pagesjaunes.fr/annuaire/saint-denis-974/assurances-courtiers ; https://www.assurco-assurance-reunion.fr/ ; https://www.courtierassurances.re/ ; https://www.cea-assurances.fr/nos-agences/agence-reunion/
A11: 10 | B11: JCS Courtage EURL | C11: Courtage & assurance | D11: 1 | E11: Saint-Denis | F11: 18 rue Ruisseau des Noirs, 97400 | G11: 02 62 97 59 71 | J11: Atlas | K11: Données sensibles des assurés : usage maîtrisé de l'IA, RGPD et preuve de mesures art. 4 (OPCO Atlas). | L11: À qualifier | O11: https://www.pagesjaunes.fr/annuaire/saint-denis-974/assurances-courtiers ; https://www.assurco-assurance-reunion.fr/ ; https://www.courtierassurances.re/ ; https://www.cea-assurances.fr/nos-agences/agence-reunion/
A12: 11 | B12: Réunion Assurances | C12: Courtage & assurance | D12: 1 | E12: Saint-Denis | F12: Bât. C Rés. Le Florentin, 45 av. Leconte de Lisle, 97490 | G12: 02 62 96 57 60 | J12: Atlas | K12: Données sensibles des assurés : usage maîtrisé de l'IA, RGPD et preuve de mesures art. 4 (OPCO Atlas). | L12: À qualifier | O12: https://www.pagesjaunes.fr/annuaire/saint-denis-974/assurances-courtiers ; https://www.assurco-assurance-reunion.fr/ ; https://www.courtierassurances.re/ ; https://www.cea-assurances.fr/nos-agences/agence-reunion/
A13: 12 | B13: AS Expertise Comptable | C13: Expertise comptable | D13: 1 | E13: Saint-Denis | F13: 41 rue Monthion, 97400 | J13: Atlas | K13: Vos collaborateurs saisissent-ils des données clients dans ChatGPT ? Formation IA + RGPD + charte d'usage, prise en charge OPCO Atlas. | L13: À qualifier | O13: https://fr.mappy.com/poi/5a6aa0500351d11fa08edb02 ; https://fr.mappy.com/poi/65e3e5aa00ef9c78bfaac72d
A14: 13 | B14: CCO Expertise | C14: Expertise comptable | D14: 1 | E14: Saint-Denis | F14: 14 ruelle Magnan, 97490 | G14: 02 62 97 89 03 | J14: Atlas | K14: Vos collaborateurs saisissent-ils des données clients dans ChatGPT ? Formation IA + RGPD + charte d'usage, prise en charge OPCO Atlas. | L14: À qualifier | O14: Recherche web 05/10/2026 – fiches Pages Jaunes (pagesjaunes.fr/pros/53172001, 63020050, 05903597) et https://www.pagesjaunes.fr/annuaire/departement/reunion-974/expertise-comptable
A15: 14 | B15: Cabinet AGCR Expertise Comptable | C15: Expertise comptable | D15: 1 | E15: Saint-Denis | F15: Rés. Anaxagore N°207, 24 rue Jean Cocteau, 97490 | G15: 02 62 20 65 00 | J15: Atlas | K15: Vos collaborateurs saisissent-ils des données clients dans ChatGPT ? Formation IA + RGPD + charte d'usage, prise en charge OPCO Atlas. | L15: À qualifier | O15: Recherche web 05/10/2026 – fiches Pages Jaunes (pagesjaunes.fr/pros/53172001, 63020050, 05903597) et https://www.pagesjaunes.fr/annuaire/departement/reunion-974/expertise-comptable | P15: 20 à 49 salariés : bonne taille pour un intra
A16: 15 | B16: Cabinet Ah Foune et Associés | C16: Expertise comptable | D16: 1 | E16: Saint-Denis | F16: 42 rue Jules Olivier ou 64 rue Roland Garros, 97400 (sources divergentes) | J16: Atlas | K16: Vos collaborateurs saisissent-ils des données clients dans ChatGPT ? Formation IA + RGPD + charte d'usage, prise en charge OPCO Atlas. | L16: À qualifier | O16: https://finalib.fr/expert/cabinet-ah-foune-et-associes-expert-comptable-saint-denis-a7eab0 ; https://www.pagesjaunes.fr/annuaire/departement/reunion-974/expertise-comptable | P16: Adresse à confirmer au premier appel
A17: 16 | B17: Casabona | C17: Expertise comptable | D17: 1 | E17: Saint-Pierre | F17: 7 allée Piscine, 97410 | J17: Atlas | K17: Vos collaborateurs saisissent-ils des données clients dans ChatGPT ? Formation IA + RGPD + charte d'usage, prise en charge OPCO Atlas. | L17: À qualifier | O17: https://comptable-lesexpertsdusud.re/ ; https://demarchesadministratives.fr/expert-comptable/saint-pierre-97410
A18: 17 | B18: D.C.A | C18: Expertise comptable | D18: 1 | E18: Saint-Denis | F18: 181 rue Jules Auber, 97400 | G18: 02 62 41 25 26 | J18: Atlas | K18: Vos collaborateurs saisissent-ils des données clients dans ChatGPT ? Formation IA + RGPD + charte d'usage, prise en charge OPCO Atlas. | L18: À qualifier | O18: Recherche web 05/10/2026 – fiches Pages Jaunes (pagesjaunes.fr/pros/53172001, 63020050, 05903597) et https://www.pagesjaunes.fr/annuaire/departement/reunion-974/expertise-comptable
A19: 18 | B19: EC Réunion | C19: Expertise comptable | D19: 1 | E19: Saint-Denis | F19: 248 rue Maréchal Leclerc, 97400 | G19: 02 62 93 88 88 | J19: Atlas | K19: Vos collaborateurs saisissent-ils des données clients dans ChatGPT ? Formation IA + RGPD + charte d'usage, prise en charge OPCO Atlas. | L19: À qualifier | O19: Recherche web 05/10/2026 – fiches Pages Jaunes (pagesjaunes.fr/pros/53172001, 63020050, 05903597) et https://www.pagesjaunes.fr/annuaire/departement/reunion-974/expertise-comptable
A20: 19 | B20: FIDUCIAL Expertise Saint-Denis | C20: Expertise comptable | D20: 1 | E20: Saint-Denis | F20: 6 rue de Lescouble, 97400 | G20: 02 62 72 18 50 | J20: Atlas | K20: Vos collaborateurs saisissent-ils des données clients dans ChatGPT ? Formation IA + RGPD + charte d'usage, prise en charge OPCO Atlas. | L20: À qualifier | O20: Recherche web 05/10/2026 – fiches Pages Jaunes (pagesjaunes.fr/pros/53172001, 63020050, 05903597) et https://www.pagesjaunes.fr/annuaire/departement/reunion-974/expertise-comptable
A21: 20 | B21: Les Experts du Sud | C21: Expertise comptable | D21: 1 | E21: Saint-Pierre | F21: 13 rue Bory Saint-Vincent, Rés. Guetali, ZAC Bank, 97410 | G21: 02 62 25 15 61 | I21: https://comptable-lesexpertsdusud.re/ | J21: Atlas | K21: Vos collaborateurs saisissent-ils des données clients dans ChatGPT ? Formation IA + RGPD + charte d'usage, prise en charge OPCO Atlas. | L21: À qualifier | O21: https://comptable-lesexpertsdusud.re/ ; https://demarchesadministratives.fr/expert-comptable/saint-pierre-97410
A22: 21 | B22: Medon & Associés | C22: Expertise comptable | D22: 1 | E22: Saint-Denis | F22: 21 rue Jules Auber, 97400 | I22: https://www.hlb.global/reunion | J22: Atlas | K22: Vos collaborateurs saisissent-ils des données clients dans ChatGPT ? Formation IA + RGPD + charte d'usage, prise en charge OPCO Atlas. | L22: À qualifier | O22: https://www.pappers.fr/entreprise/451726152 ; https://finalib.fr/expert/medon-associes-expert-comptable-saint-denis-51ae12 | P22: En procédure de sauvegarde depuis le 08/02/2026 : budget formation probablement gelé, pas prioritaire
A23: 22 | B23: Valentis Conseil & Audit | C23: Expertise comptable | D23: 1 | E23: Saint-Denis | F23: 22 chemin Dufourg les Bas, 97400 | J23: Atlas | K23: Vos collaborateurs saisissent-ils des données clients dans ChatGPT ? Formation IA + RGPD + charte d'usage, prise en charge OPCO Atlas. | L23: À qualifier | O23: https://fr.mappy.com/poi/5a6aa0500351d11fa08edb02 ; https://fr.mappy.com/poi/65e3e5aa00ef9c78bfaac72d
A24: 23 | B24: Getim | C24: Immobilier | D24: 1 | E24: Saint-Denis | F24: 4 avenue de la Victoire, 97400 (+ agence à Saint-Pierre) | G24: 02 62 21 12 61 | I24: https://www.getim.com/ | J24: À vérifier | K24: Annonces, comptes rendus de visite, réponses aux mandants : l'IA au service de l'agence, dans les règles RGPD. | L24: À qualifier | O24: https://www.orpi.com/mvsnord/ ; https://www.getim.com/ ; https://isautier.re/ ; https://www.sixiemeavenue.com/agences/saint-denis974/ ; https://kaze-immobilier.fr/ | P24: Attention : un homonyme « Getim » en Algérie apparaît dans les recherches d'email, ne pas confondre
A25: 24 | B25: Guy Hoquet Saint-Denis | C25: Immobilier | D25: 1 | E25: Saint-Denis | F25: 13 rue Charles Gounod, 97400 | G25: 02 62 41 66 00 | H25: saintdenis@guyhoquet.re | I25: https://la-reunion-saint-denis.guy-hoquet.com/ | J25: À vérifier | K25: Annonces, comptes rendus de visite, réponses aux mandants : l'IA au service de l'agence, dans les règles RGPD. | L25: À qualifier | O25: https://la-reunion-saint-denis.guy-hoquet.com/mon-agence ; https://la-reunion-saint-pierre.guy-hoquet.com/mon-agence
A26: 25 | B26: Guy Hoquet Saint-Pierre | C26: Immobilier | D26: 1 | E26: Saint-Pierre | F26: 78 bis bd Hubert Delisle, 97410 | G26: 02 62 27 90 90 | H26: saintpierre@guyhoquet.re | I26: https://la-reunion-saint-pierre.guy-hoquet.com/ | J26: À vérifier | K26: Annonces, comptes rendus de visite, réponses aux mandants : l'IA au service de l'agence, dans les règles RGPD. | L26: À qualifier | O26: https://la-reunion-saint-denis.guy-hoquet.com/mon-agence ; https://la-reunion-saint-pierre.guy-hoquet.com/mon-agence
A27: 26 | B27: Isautier Immobilier | C27: Immobilier | D27: 1 | E27: Saint-Denis | F27: 11 rue Juliette Dodu, 97400 | G27: 02 62 55 05 50 | I27: https://isautier.re/ | J27: À vérifier | K27: Annonces, comptes rendus de visite, réponses aux mandants : l'IA au service de l'agence, dans les règles RGPD. | L27: À qualifier | O27: https://www.orpi.com/mvsnord/ ; https://www.getim.com/ ; https://isautier.re/ ; https://www.sixiemeavenue.com/agences/saint-denis974/ ; https://kaze-immobilier.fr/
A28: 27 | B28: Kaze Immobilier | C28: Immobilier | D28: 1 | E28: Saint-Denis | I28: https://kaze-immobilier.fr/ | J28: À vérifier | K28: Annonces, comptes rendus de visite, réponses aux mandants : l'IA au service de l'agence, dans les règles RGPD. | L28: À qualifier | O28: https://www.orpi.com/mvsnord/ ; https://www.getim.com/ ; https://isautier.re/ ; https://www.sixiemeavenue.com/agences/saint-denis974/ ; https://kaze-immobilier.fr/
A29: 28 | B29: Orpi MVS (Saint-Denis, Saint-Gilles, Saint-Pierre) | C29: Immobilier | D29: 1 | E29: Saint-Denis | F29: 55 rue Labourdonnais, 97400 (+ 103 rue du Général de Gaulle, Saint-Gilles ; 30 rue de la Cayenne, Saint-Pierre) | G29: 02 62 51 74 74 | I29: https://www.orpi.com/mvs/ | J29: À vérifier | K29: Annonces, comptes rendus de visite, réponses aux mandants : l'IA au service de l'agence, dans les règles RGPD. | L29: À qualifier | O29: https://www.orpi.com/mvsnord/ ; https://www.getim.com/ ; https://isautier.re/ ; https://www.sixiemeavenue.com/agences/saint-denis974/ ; https://kaze-immobilier.fr/ | P29: 3 agences : proposer un intra commun
A30: 29 | B30: Sixième Avenue Saint-Denis | C30: Immobilier | D30: 1 | E30: Saint-Denis | I30: https://www.sixiemeavenue.com/agences/saint-denis974/ | J30: À vérifier | K30: Annonces, comptes rendus de visite, réponses aux mandants : l'IA au service de l'agence, dans les règles RGPD. | L30: À qualifier | O30: https://www.orpi.com/mvsnord/ ; https://www.getim.com/ ; https://isautier.re/ ; https://www.sixiemeavenue.com/agences/saint-denis974/ ; https://kaze-immobilier.fr/
A31: 30 | B31: NOT'AVENIR Notaires | C31: Notariat | D31: 1 | E31: Saint-Paul | F31: 8 rue Évariste de Parny, 97460 (+ Saint-Denis : 66 rue Labourdonnais, 02 62 73 08 08) | G31: 02 62 45 45 65 | I31: https://notavenir.notaires.fr/ | J31: OPCO EP | K31: Secret professionnel + IA : quelles pratiques autorisées ? Formation et charte pour l'étude (OPCO EP). | L31: À qualifier | O31: https://notavenir.notaires.fr/ ; https://notaires-pasteur.notaires.fr/ ; https://chambre-reunion.notaires.fr/notaire/
A32: 31 | B32: Notaires Pasteur | C32: Notariat | D32: 1 | E32: Saint-Denis | F32: 44 rue Pasteur, 97400 | G32: 02 62 90 14 14 | I32: https://notaires-pasteur.notaires.fr/ | J32: OPCO EP | K32: Secret professionnel + IA : quelles pratiques autorisées ? Formation et charte pour l'étude (OPCO EP). | L32: À qualifier | O32: https://notavenir.notaires.fr/ ; https://notaires-pasteur.notaires.fr/ ; https://chambre-reunion.notaires.fr/notaire/
A33: 32 | B33: Office notarial Aubert et associés | C33: Notariat | D33: 1 | E33: Saint-Pierre | F33: 32 rue Luc Lorion, 97453 Saint-Pierre Cedex | G33: 02 62 25 00 89 | J33: OPCO EP | K33: Secret professionnel + IA : quelles pratiques autorisées ? Formation et charte pour l'étude (OPCO EP). | L33: À qualifier | O33: https://notavenir.notaires.fr/ ; https://notaires-pasteur.notaires.fr/ ; https://chambre-reunion.notaires.fr/notaire/
A34: 33 | B34: Étude Gaudieux | C34: Notariat | D34: 1 | E34: Saint-Denis | F34: 62 bd du Chaudron, Centre d'affaires Cadjee, Bât. A, 9e ét., 97400 | G34: 02 62 15 08 40 | J34: OPCO EP | K34: Secret professionnel + IA : quelles pratiques autorisées ? Formation et charte pour l'étude (OPCO EP). | L34: À qualifier | O34: https://notavenir.notaires.fr/ ; https://notaires-pasteur.notaires.fr/ ; https://chambre-reunion.notaires.fr/notaire/
A35: 34 | B35: ABCD Mobilier | C35: Commerce de gros | D35: 2 | I35: https://www.abcd-mobilier.fr/ | J35: AKTO | K35: Devis, fiches produits, relances : 1 journée pour gagner du temps avec l'IA sans exposer vos données clients (OPCO AKTO). | L35: À qualifier | O35: https://www.pagesjaunes.fr/annuaire/departement/la-reunion-974/mobilier-de-bureau ; https://offital.com/ ; https://bureauxetobjets.com/
A36: 35 | B36: Adéquation Mobilier | C36: Commerce de gros | D36: 2 | E36: Saint-Denis | F36: 30 route Piton Bois de Nèfles | J36: AKTO | K36: Devis, fiches produits, relances : 1 journée pour gagner du temps avec l'IA sans exposer vos données clients (OPCO AKTO). | L36: À qualifier | O36: https://www.pagesjaunes.fr/annuaire/departement/la-reunion-974/mobilier-de-bureau ; https://offital.com/ ; https://bureauxetobjets.com/
A37: 36 | B37: BUROCA | C37: Commerce de gros | D37: 2 | E37: Sainte-Marie | F37: 6 rue Concorde, Innovespace A03 Duparc, 97438 | J37: AKTO | K37: Devis, fiches produits, relances : 1 journée pour gagner du temps avec l'IA sans exposer vos données clients (OPCO AKTO). | L37: À qualifier | O37: https://www.pagesjaunes.fr/annuaire/departement/la-reunion-974/mobilier-de-bureau ; https://offital.com/ ; https://bureauxetobjets.com/
A38: 37 | B38: BUROLIKE | C38: Commerce de gros | D38: 2 | E38: Sainte-Marie | F38: 2 rue du Soleil, PAE La Mare, 97438 | J38: AKTO | K38: Devis, fiches produits, relances : 1 journée pour gagner du temps avec l'IA sans exposer vos données clients (OPCO AKTO). | L38: À qualifier | O38: https://www.pagesjaunes.fr/annuaire/departement/la-reunion-974/mobilier-de-bureau ; https://offital.com/ ; https://bureauxetobjets.com/
A39: 38 | B39: Blanche Entreprises | C39: Commerce de gros | D39: 2 | E39: Saint-Denis | F39: 2 route Rivière des Pluies | J39: AKTO | K39: Devis, fiches produits, relances : 1 journée pour gagner du temps avec l'IA sans exposer vos données clients (OPCO AKTO). | L39: À qualifier | O39: https://www.pagesjaunes.fr/annuaire/departement/la-reunion-974/mobilier-de-bureau ; https://offital.com/ ; https://bureauxetobjets.com/
A40: 39 | B40: Bureaux & Objets Réunion | C40: Commerce de gros | D40: 2 | E40: Saint-Pierre | I40: https://bureauxetobjets.com/ | J40: AKTO | K40: Devis, fiches produits, relances : 1 journée pour gagner du temps avec l'IA sans exposer vos données clients (OPCO AKTO). | L40: À qualifier | O40: https://www.pagesjaunes.fr/annuaire/departement/la-reunion-974/mobilier-de-bureau ; https://offital.com/ ; https://bureauxetobjets.com/
...

Sheet Grands comptes
A1: Groupe | B1: Secteur | C1: Repère | D1: Approche conseillée | E1: Statut | F1: Source
A2: Groupe Bernard Hayot (GBH) | B2: Distribution, automobile, industrie | C2: 1er groupe privé de l'île (≈ 7 100 salariés, ≈ 1,9 Md€ de CA selon le classement) | D2: Contacter la DRH / le responsable formation ; souvent achat par consultation : proposer un pilote d'une journée « Pack Article 4 » pour un service. | E2: À qualifier | F2: https://www.marketing-management.io/blog/top-40-entreprises-a-la-reunion
A3: Vindémia | B3: Grande distribution | C3: Top 10 | D3: Contacter la DRH / le responsable formation ; souvent achat par consultation : proposer un pilote d'une journée « Pack Article 4 » pour un service. | E3: À qualifier | F3: https://www.marketing-management.io/blog/top-40-entreprises-a-la-reunion
A4: Groupe Caillé | B4: Automobile, distribution | C4: Top 10 (≈ 623 M€ de CA) | D4: Contacter la DRH / le responsable formation ; souvent achat par consultation : proposer un pilote d'une journée « Pack Article 4 » pour un service. | E4: À qualifier | F4: https://www.marketing-management.io/blog/top-40-entreprises-a-la-reunion
A5: Groupe Excellence | B5: Automobile | C5: Top 10 | D5: Contacter la DRH / le responsable formation ; souvent achat par consultation : proposer un pilote d'une journée « Pack Article 4 » pour un service. | E5: À qualifier | F5: https://www.marketing-management.io/blog/top-40-entreprises-a-la-reunion
A6: Air Austral | B6: Transport aérien | C6: Top 10 | D6: Contacter la DRH / le responsable formation ; souvent achat par consultation : proposer un pilote d'une journée « Pack Article 4 » pour un service. | E6: À qualifier | F6: https://www.marketing-management.io/blog/top-40-entreprises-a-la-reunion
A7: Groupe Ravate | B7: Distribution | C7: Top 10 | D7: Contacter la DRH / le responsable formation ; souvent achat par consultation : proposer un pilote d'une journée « Pack Article 4 » pour un service. | E7: À qualifier | F7: https://www.marketing-management.io/blog/top-40-entreprises-a-la-reunion
A8: Groupe Marbour | B8: Distribution | C8: Top 10 | D8: Contacter la DRH / le responsable formation ; souvent achat par consultation : proposer un pilote d'une journée « Pack Article 4 » pour un service. | E8: À qualifier | F8: https://www.marketing-management.io/blog/top-40-entreprises-a-la-reunion
A9: Groupe Urcoopa | B9: Agroalimentaire, coopérative | C9: Top 10 | D9: Contacter la DRH / le responsable formation ; souvent achat par consultation : proposer un pilote d'une journée « Pack Article 4 » pour un service. | E9: À qualifier | F9: https://www.marketing-management.io/blog/top-40-entreprises-a-la-reunion
A10: Tereos Océan Indien | B10: Sucre, industrie | C10: Top 10 | D10: Contacter la DRH / le responsable formation ; souvent achat par consultation : proposer un pilote d'une journée « Pack Article 4 » pour un service. | E10: À qualifier | F10: https://www.marketing-management.io/blog/top-40-entreprises-a-la-reunion
A11: Groupe Océinde | B11: Énergie, distribution | C11: ≈ 360 M€ de CA | D11: Contacter la DRH / le responsable formation ; souvent achat par consultation : proposer un pilote d'une journée « Pack Article 4 » pour un service. | E11: À qualifier | F11: https://www.marketing-management.io/blog/top-40-entreprises-a-la-reunion
A12: Coopérative U La Réunion | B12: Grande distribution | C12: Classement 2025 | D12: Contacter la DRH / le responsable formation ; souvent achat par consultation : proposer un pilote d'une journée « Pack Article 4 » pour un service. | E12: À qualifier | F12: https://www.marketing-management.io/blog/top-40-entreprises-a-la-reunion
... A14: ADIR (Association pour le développement industriel) | B14: Réseau de ≈ 200 industriels | C14: Prescripteur : intervention lors d'un événement adhérents | D14: Contacter la DRH / le responsable formation ; souvent achat par consultation : proposer un pilote d'une journée « Pack Article 4 » pour un service. | E14: À qualifier | F14: https://adir.re/

Sheet Sous-traitance OF
A1: Organisme | B1: Zone | C1: Type | D1: Domaines | E1: Adresse | F1: Téléphone | G1: Email | H1: Site web | I1: Pourquoi vous / action | J1: Priorité | K1: Statut | L1: Date candidature | M1: Source
A2: Honoris Educational Network | B2: Maurice | C2: Organisme agréé MQA | D2: Soft skills, Microsoft Office, automatisation, data, marketing digital | H2: https://honoris.ac.mu/mqa-approved-training-programmes-mauritius/ | I2: Partenariat : formation IA éligible au remboursement HRDC jusqu'à 90 % | J2: A | K2: À contacter | M2: https://honoris.ac.mu/mqa-approved-training-programmes-mauritius/
A3: SMFP – Société mahoraise de formation professionnelle | B3: Mayotte – Mamoudzou | C3: OF 976 (Qualiopi) | D3: Numérique (CléA), social | E3: Mamoudzou | H3: https://www.smfp-site.fr/ | I3: Numérique + IA à Mayotte (AAP France 2030 Mayotte ouvert jusqu'au 31/12/2026) | J3: A | K3: À contacter | M3: https://www.intercariforef.org/formations/societe-mahoraise-de-formation-professionnelle-smfp/organisme-39_216.html
A4: Senza Formations | B4: Métropole → 974 | C4: OF national, sessions à Saint-Denis | D4: IA générative | E4: Sessions à Saint-Denis (28/09-28/10 et 30/11-30/12/2026) | H4: https://senza-formations.com/ville/saint-denis/formation-initiation-lintelligence-artificielle-ia | I4: Programme des sessions IA à Saint-Denis : il leur faut un formateur local | J4: A | K4: À contacter | M4: https://senza-formations.com/ville/saint-denis/formation-initiation-lintelligence-artificielle-ia
A5: VIAgence | B5: Métropole → 974 | C5: OF qui vend dans le 974 | D5: IA | E5: 32 rue de Paris, 92100 Boulogne-Billancourt | F5: 01 79 35 52 37 | G5: contact@viagence.com | I5: Vend du présentiel à Saint-Denis sans être implanté : proposez-vous comme formateur sur place (modèle d'email dans opportunites.md) | J5: A | K5: À contacter | M5: Programme reçu par votre amie
A6: A'Venir | B6: Réunion | C6: OF 974 (Qualiopi) | D6: Passerelle IA | H6: https://a-venir.re/ | I6: Co-animation « Passerelle IA » | J6: A | K6: À contacter | M6: https://a-venir.re/
A7: CCI Réunion (+ CFA Campus Pro Saint-Pierre) | B7: Réunion | C7: Consulaire | D7: IA et productivité, commerce, vente, gestion | E7: CFA : 65 rue du Père Lafosse, 97410 Saint-Pierre | H7: https://reunion.cci.fr/formation/166206/ia-et-productivite-outils-et-bonnes-pratiques | I7: Catalogue « IA et productivité » + CFA commerce et vente : être référencé comme intervenant | J7: A | K7: À contacter | M7: https://reunion.cci.fr/se-former/ecolescentres-de-formations/liste-des-nos-ecoles-cfa
A8: CFA Disciplina | B8: Réunion | C8: CFA | D8: Vente | I8: Cherchait des formateurs vente indépendants | J8: A | K8: À contacter | M8: https://candidat.francetravail.fr/offres/emploi/formateur/reunion/s20m22d974
A9: IFR – Institut de Formation de la Réunion | B9: Réunion | C9: OF 974 | D9: IA pour tous, commerce, informatique, communication digitale | H9: https://www.ifr-reunion.re/formation-ia-pour-tous/ | I9: Module « IA + RGPD » en complément de « IA pour tous » | J9: A | K9: À contacter | M9: https://www.ifr-reunion.re/formation-ia-pour-tous/
A10: JD Formations | B10: Réunion | C10: OF 974 | D10: IA (ChatGPT), métiers | H10: https://www.jdformations.re/formation-ia-chatgpt-a-la-reunion-974/ | I10: Formation IA par métier : proposez co-animation et module conformité | J10: A | K10: À contacter | M10: https://www.jdformations.re/formation-ia-chatgpt-a-la-reunion-974/
A11: Numeria | B11: Réunion | C11: OF 974 | D11: IA, numérique | H11: https://www.numeria-formation.re/formations-intelligence-artificielle/ | I11: Organise des formations IA : proposez le volet RGPD / IA Act et du renfort de formateurs | J11: A | K11: À contacter | M11: https://www.numeria-formation.re/formations-intelligence-artificielle/
A12: Réunion Prospectives Compétences (Carif-Oref) | B12: Réunion | C12: Prescripteur public | D12: Information sur la formation (formanoo.org) | F12: 02 62 83 00 40 | G12: contact@rpc.re | H12: https://www.rpc.re | I12: Faites référencer vos formations sur formanoo.org : visibilité auprès des prescripteurs | J12: A | K12: À contacter | M12: https://centre-inffo.fr/content/uploads/2024/06/depliant-reseaux-062024.pdf
A13: Sarl Laboratoire L & M | B13: Réunion | C13: OF 974 | D13: Management, comptabilité, numérique / cybersécurité, bureautique, vente (+ pâtisserie, HACCP) | I13: A publié des offres de formateurs en management, numérique et techniques de vente | J13: A | K13: À contacter | M13: https://candidat.francetravail.fr/offres/emploi/formateur/reunion/s20m22d974
A14: DCP Formation | B14: Réunion – Le Tampon + Mayotte | C14: Réseau national, centres locaux | D14: Informatique, IA, management, RH, comptabilité | E14: 4 rue du Collège, Plaine des Cafres, 97418 Le Tampon (+ centre à Mamoudzou) | H14: https://dcpformation.fr/centre_de_formation/letampon-974/ | I14: Affiche l'IA et le management, et un centre à Mayotte : 2 territoires possibles | J14: A | K14: À contacter | M14: https://dcpformation.fr/centre_de_formation/letampon-974/
A15: Digitalys | B15: Réunion – Saint-André | C15: OF 974 | D15: Soft skills, numérique | E15: 825 avenue des Mascareignes, 97440 Saint-André | F15: 02 62 73 83 52 | G15: contact@digitalysformation.fr | I15: Soft skills + numérique : votre double profil | J15: A | K15: À contacter | M15: https://www.capitecorpus.com/formation-communication-soft-skills/
A16: AKADEMIA FORMATION | B16: Réunion – Saint-Denis | C16: OF 974 | D16: IA | E16: Saint-Denis 97400 | I16: Annonce « formateur indépendant – Initiation à l'IA » (7 h, présentiel) : candidatez si elle est encore en ligne | J16: A | K16: À contacter | M16: https://fr.indeed.com/q-formateur-ia-l-la-r%C3%A9union-emplois.html
A17: CQFD Pro | B17: Réunion – Saint-Denis | C17: OF 974 | D17: Formation continue sur mesure en entreprise | E17: Saint-Denis | I17: Formation sur mesure en entreprise : votre cœur de métier (vente, management, IA) | J17: A | K17: À contacter | M17: https://www.pagesjaunes.fr/annuaire/saint-denis-974/organisme-de-formation
A18: GRETA Réunion (antenne Nord) | B18: Réunion – Saint-Denis | C18: Public (Éducation nationale) | D18: IA générative (RS 6776), tous domaines | E18: Saint-Denis | H18: https://ftlvreunion.fr/en-ce-moment/news/formation-ia-generative-en-presentiel.html | I18: Sessions IA du 16 au 18/11/2026 : vacations, module éthique et conformité | J18: A | K18: À contacter | M18: https://ftlvreunion.fr/en-ce-moment/news/formation-ia-generative-en-presentiel.html
A19: Educatis Forma | B19: Réunion – Saint-Paul | C19: OF 974 | D19: Négociation commerciale, assistanat | E19: Saint-Paul | I19: Recrutait des formateurs en négociation commerciale | J19: A | K19: À contacter | M19: https://candidat.francetravail.fr/offres/emploi/formateur/reunion/s20m22d974
A20: Axam Formation | B20: Réunion – Saint-Pierre | C20: Réseau national | D20: Informatique, bureautique, Power BI | E20: Saint-Pierre 974 | H20: https://www.axamformation.fr/informatique-saint-pierre/974 | I20: Ajoutez l'IA à leur catalogue bureautique (Copilot, Gemini) | J20: A | K20: À contacter | M20: https://www.axamformation.fr/informatique-saint-pierre/974
A21: Agepac Formation | B21: Réunion – Sainte-Clotilde | C21: CFA / OF (Qualiopi) | D21: BTS MCO, GPME, assurance | E21: Sainte-Clotilde, 97490 Saint-Denis | H21: https://www.wizbii.com/company/agepac | I21: BTS MCO = management commercial : vente, management, IA | J21: A | K21: À contacter | M21: https://www.wizbii.com/company/agepac/job/assistant-commercial-gestion-et-relation-client-pro-pme-h-f-bts-mco-en-alternance-age13562
A22: Appavoo Business School | B22: Maurice | C22: Organisme agréé MQA | D22: Formation en entreprise | H22: https://appavoo.com/education-n-training/ | I22: Partenariat IA + vente / management | J22: B | K22: À contacter | M22: https://appavoo.com/education-n-training/
A23: IT Academy | B23: Maurice – Port-Louis | C23: Centre agréé MQA | D23: Certifications informatiques | E23: Port-Louis | H23: https://www.facebook.com/itacademy.mu/ | I23: Module IA appliquée | J23: B | K23: À contacter | M23: https://www.facebook.com/itacademy.mu/
A24: ESCGM – École supérieure de commerce et de gestion de Mayotte | B24: Mayotte | C24: École / OF | D24: Informatique, développeur web, commerce | I24: IA et RGPD dans les cursus informatique et commerce | J24: B | K24: À contacter | M24: https://www.intercariforef.org/formations/cole-suprieur-de-commerce-et-de-gestion-de-mayotte.-escgm/organisme-39_225.html
A25: ITG Learning | B25: Métropole → 974 | C25: OF qui porte des formateurs indépendants | D25: IA, tous domaines | I25: Déjà utilisé par un formateur IA du 974 pour la prise en charge OPCO. Vous avez votre propre Qualiopi : proposez-leur l'inverse, des missions en sous-traitance | J25: B | K25: À contacter | M25: https://jmberthelot.com/formation-intelligence-artificielle-la-reunion.html
A26: CNFPT – délégation Réunion | B26: Réunion | C26: Public (agents territoriaux) | D26: Formation des collectivités | H26: https://www.cnfpt.fr/se-former/suivre-formation/inscription-ligne/vos-interlocuteurs-formation-a-delegation-reunion/vos-contacts-a-delegation-reunion/reunion | I26: Les collectivités se forment à l'IA : se faire référencer comme intervenant | J26: B | K26: À contacter | M26: https://www.cnfpt.fr/se-former/suivre-formation/inscription-ligne/vos-interlocuteurs-formation-a-delegation-reunion/vos-contacts-a-delegation-reunion/reunion
A27: Simplon (partenaire de l'AFPAR) | B27: Réunion | C27: OF national | D27: Développeur IA | I27: Module conformité IA Act / RGPD dans la formation développeur IA | J27: B | K27: À contacter | M27: https://outremers360.com/bassin-indien-appli/la-reunion-une-premiere-formation-de-developpeur-en-intelligence-artificielle-pour-le-territoire
A28: AFPAR | B28: Réunion (4 centres) | C28: Organisme régional | D28: 150 formations, parcours développeur IA | E28: Centres de Saint-André, Saint-Denis, Saint-Paul, Saint-Pierre | H28: https://afpar.re/ | I28: Intervenant « éthique, RGPD, IA Act » dans le parcours IA | J28: B | K28: À contacter | M28: https://afpar.re/
A29: Envergure | B29: Réunion – La Possession | C29: OF 974 (Qualiopi) | D29: Accompagnement de consultants indépendants | E29: 5 rue Justin Baptiste, 97419 La Possession | I29: Travaille avec des consultants indépendants : partenariat naturel | J29: B | K29: À contacter | M29: https://www.pagesjaunes.fr/annuaire/le-port-974/organisme-de-formation
A30: ILOI – Institut de l'Image de l'Océan Indien | B30: Réunion – Le Port | C30: École | D30: Audiovisuel, création numérique, IA | E30: Le Port | I30: Recrutait des formateurs externes 2026-2027 avec un module IA (clos le 24/09) : candidature spontanée | J30: B | K30: À contacter | M30: Résultat de recherche e-marchespublics.com
A31: CFA Horizon Réunion | B31: Réunion – Le Tampon | C31: CFA (Qualiopi) | D31: Vente, commerce, marketing (Bac à Bac+3) | E31: 4 boulevard Michel Debré, 97430 Le Tampon | I31: Vente + IA appliquée au commerce | J31: B | K31: À contacter | M31: https://www.pagesjaunes.fr/pros/12005556
A32: Form'aou | B32: Réunion – Saint-André + Saint-Louis | C32: OF / CFA | D32: Commerce, administration, coiffure | E32: Saint-André (+ centre à Saint-Louis) | I32: Commerce et vente | J32: B | K32: À contacter | M32: https://candidat.francetravail.fr/offres/emploi/formateur/reunion/s20m22d974
A33: Advance Formation & Développement | B33: Réunion – Saint-Benoît | C33: OF 974 | D33: Soft skills | E33: Saint-Benoît | H33: https://www.mesenseignes.fr/advance-formation-developpement/5167-formation-soft-skills-a-lile-de-la-reunion-974/ | I33: Soft skills : votre expertise historique | J33: B | K33: À contacter | M33: https://www.mesenseignes.fr/advance-formation-developpement/5167-formation-soft-skills-a-lile-de-la-reunion-974/
A34: Run Paye Formation | B34: Réunion – Saint-Benoît | C34: OF 974 | D34: Paie, gestion | E34: 55 rue Auguste de Villèle, 97470 Saint-Benoît | I34: IA et RGPD pour les gestionnaires de paie (données sensibles) | J34: B | K34: À contacter | M34: https://www.pagesjaunes.fr/annuaire/saint-benoit-974/formation-professionnelle
A35: CFA de l'Université de La Réunion / FTLV | B35: Réunion – Saint-Denis | C35: Public (université) | D35: Tertiaire, numérique | E35: 2 rue Joseph Wetzell, 97400 Saint-Denis | H35: https://ftlvreunion.fr/ | I35: Intervenant professionnel IA / RGPD en licence pro et formation continue | J35: B | K35: À contacter | M35: http://geolocalisation.onisep.fr/974-la-reunion/saint-denis/cfa/centre-de-formation-d-apprentis-de-l-universite-de-la-reunion-universite-de-la-reunion.html
A36: EAFC – École académique de la formation continue | B36: Réunion – Saint-Denis | C36: Public (académie) | D36: Formation continue | E36: 24 avenue Georges Brassens, 97400 Saint-Denis | F36: 02 62 48 13 39 | I36: Recrute des intervenants vacataires : dossier de candidature | J36: B | K36: À contacter | M36: https://www.ac-reunion.fr/media/46832/download
A37: Develop'A Ou | B37: Réunion – Saint-Leu | C37: OF 974 (Qualiopi) | D37: Bureautique, informatique, accueil, petite enfance | E37: 5 chemin des Francisceas, 97425 Saint-Leu | I37: IA dans les formations bureautique | J37: B | K37: À contacter | M37: https://www.pagesjaunes.fr/annuaire/saint-leu-974/apprentissage-formation-professionnelle
A38: Ariane Formation | B38: Réunion – Saint-Paul | C38: OF 974 (Qualiopi depuis 2003) | D38: Formation continue | E38: 6 route de Savanna, 97460 Saint-Paul | H38: https://www.ariane-formation.re/ | I38: Candidature spontanée | J38: B | K38: À contacter | M38: https://www.ariane-formation.re/
A39: Capital Formation | B39: Réunion – Saint-Paul | C39: OF 974 (Qualiopi, 20 ans) | D39: Formation continue, bilan, apprentissage | E39: 171 Chaussée Royale, 1er étage, 97460 Saint-Paul | I39: Candidature : management, vente, IA | J39: B | K39: À contacter | M39: https://www.pagesjaunes.fr/annuaire/saint-paul-974/formation-professionnelle
A40: AREFIP | B40: Réunion – Saint-Pierre | C40: OF 974 (Qualiopi depuis l'origine) | D40: Formation professionnelle, informatique, solutions RH | E40: 24 Cité de la Plaine, 97410 Saint-Pierre | F40: 02 62 96 19 79 | H40: https://www.arefip.fr/ | I40: Informatique + RH : IA et RGPD pour les fonctions RH | J40: B | K40: À contacter | M40: https://www.arefip.fr/
...

Sheet Synthèse
A1: Tableau de bord prospection (se met à jour quand vous changez les statuts)
A3: Secteur | B3: Priorité | C3: Nb entreprises | D3: Avec téléphone | E3: Contactés | F3: RDV | G3: Clients | H3: Oppositions
A4: Cabinets d'avocats | B4: 1 | C4: =COUNTIF('Prospects 974'!$C$2:$C$107,A4) | D4: =COUNTIFS('Prospects 974'!$C$2:$C$107,A4,'Prospects 974'!$G$2:$G$107,"<>") | E4: =COUNTIFS('Prospects 974'!$C$2:$C$107,A4,'Prospects 974'!$L$2:$L$107,"Contacté")+G4+F4+COUNTIFS('Prospects 974'!$C$2:$C$107,A4,'Prospects 974'!$L$2:$L$107,"Proposition") | F4: =COUNTIFS('Prospects 974'!$C$2:$C$107,A4,'Prospects 974'!$L$2:$L$107,"RDV") | G4: =COUNTIFS('Prospects 974'!$C$2:$C$107,A4,'Prospects 974'!$L$2:$L$107,"Client") | H4: =COUNTIFS('Prospects 974'!$C$2:$C$107,A4,'Prospects 974'!$L$2:$L$107,"Opposition RGPD")
A5: Courtage & assurance | B5: 1 | C5: =COUNTIF('Prospects 974'!$C$2:$C$107,A5) | D5: =COUNTIFS('Prospects 974'!$C$2:$C$107,A5,'Prospects 974'!$G$2:$G$107,"<>") | E5: =COUNTIFS('Prospects 974'!$C$2:$C$107,A5,'Prospects 974'!$L$2:$L$107,"Contacté")+G5+F5+COUNTIFS('Prospects 974'!$C$2:$C$107,A5,'Prospects 974'!$L$2:$L$107,"Proposition") | F5: =COUNTIFS('Prospects 974'!$C$2:$C$107,A5,'Prospects 974'!$L$2:$L$107,"RDV") | G5: =COUNTIFS('Prospects 974'!$C$2:$C$107,A5,'Prospects 974'!$L$2:$L$107,"Client") | H5: =COUNTIFS('Prospects 974'!$C$2:$C$107,A5,'Prospects 974'!$L$2:$L$107,"Opposition RGPD")
A6: Expertise comptable | B6: 1 | C6: =COUNTIF('Prospects 974'!$C$2:$C$107,A6) | D6: =COUNTIFS('Prospects 974'!$C$2:$C$107,A6,'Prospects 974'!$G$2:$G$107,"<>") | E6: =COUNTIFS('Prospects 974'!$C$2:$C$107,A6,'Prospects 974'!$L$2:$L$107,"Contacté")+G6+F6+COUNTIFS('Prospects 974'!$C$2:$C$107,A6,'Prospects 974'!$L$2:$L$107,"Proposition") | F6: =COUNTIFS('Prospects 974'!$C$2:$C$107,A6,'Prospects 974'!$L$2:$L$107,"RDV") | G6: =COUNTIFS('Prospects 974'!$C$2:$C$107,A6,'Prospects 974'!$L$2:$L$107,"Client") | H6: =COUNTIFS('Prospects 974'!$C$2:$C$107,A6,'Prospects 974'!$L$2:$L$107,"Opposition RGPD")
A7: Immobilier | B7: 1 | C7: =COUNTIF('Prospects 974'!$C$2:$C$107,A7) | D7: =COUNTIFS('Prospects 974'!$C$2:$C$107,A7,'Prospects 974'!$G$2:$G$107,"<>") | E7: =COUNTIFS('Prospects 974'!$C$2:$C$107,A7,'Prospects 974'!$L$2:$L$107,"Contacté")+G7+F7+COUNTIFS('Prospects 974'!$C$2:$C$107,A7,'Prospects 974'!$L$2:$L$107,"Proposition") | F7: =COUNTIFS('Prospects 974'!$C$2:$C$107,A7,'Prospects 974'!$L$2:$L$107,"RDV") | G7: =COUNTIFS('Prospects 974'!$C$2:$C$107,A7,'Prospects 974'!$L$2:$L$107,"Client") | H7: =COUNTIFS('Prospects 974'!$C$2:$C$107,A7,'Prospects 974'!$L$2:$L$107,"Opposition RGPD")
A8: Notariat | B8: 1 | C8: =COUNTIF('Prospects 974'!$C$2:$C$107,A8) | D8: =COUNTIFS('Prospects 974'!$C$2:$C$107,A8,'Prospects 974'!$G$2:$G$107,"<>") | E8: =COUNTIFS('Prospects 974'!$C$2:$C$107,A8,'Prospects 974'!$L$2:$L$107,"Contacté")+G8+F8+COUNTIFS('Prospects 974'!$C$2:$C$107,A8,'Prospects 974'!$L$2:$L$107,"Proposition") | F8: =COUNTIFS('Prospects 974'!$C$2:$C$107,A8,'Prospects 974'!$L$2:$L$107,"RDV") | G8: =COUNTIFS('Prospects 974'!$C$2:$C$107,A8,'Prospects 974'!$L$2:$L$107,"Client") | H8: =COUNTIFS('Prospects 974'!$C$2:$C$107,A8,'Prospects 974'!$L$2:$L$107,"Opposition RGPD")
A9: Commerce de gros | B9: 2 | C9: =COUNTIF('Prospects 974'!$C$2:$C$107,A9) | D9: =COUNTIFS('Prospects 974'!$C$2:$C$107,A9,'Prospects 974'!$G$2:$G$107,"<>") | E9: =COUNTIFS('Prospects 974'!$C$2:$C$107,A9,'Prospects 974'!$L$2:$L$107,"Contacté")+G9+F9+COUNTIFS('Prospects 974'!$C$2:$C$107,A9,'Prospects 974'!$L$2:$L$107,"Proposition") | F9: =COUNTIFS('Prospects 974'!$C$2:$C$107,A9,'Prospects 974'!$L$2:$L$107,"RDV") | G9: =COUNTIFS('Prospects 974'!$C$2:$C$107,A9,'Prospects 974'!$L$2:$L$107,"Client") | H9: =COUNTIFS('Prospects 974'!$C$2:$C$107,A9,'Prospects 974'!$L$2:$L$107,"Opposition RGPD")
A10: Informatique / ESN | B10: 2 | C10: =COUNTIF('Prospects 974'!$C$2:$C$107,A10) | D10: =COUNTIFS('Prospects 974'!$C$2:$C$107,A10,'Prospects 974'!$G$2:$G$107,"<>") | E10: =COUNTIFS('Prospects 974'!$C$2:$C$107,A10,'Prospects 974'!$L$2:$L$107,"Contacté")+G10+F10+COUNTIFS('Prospects 974'!$C$2:$C$107,A10,'Prospects 974'!$L$2:$L$107,"Proposition") | F10: =COUNTIFS('Prospects 974'!$C$2:$C$107,A10,'Prospects 974'!$L$2:$L$107,"RDV") | G10: =COUNTIFS('Prospects 974'!$C$2:$C$107,A10,'Prospects 974'!$L$2:$L$107,"Client") | H10: =COUNTIFS('Prospects 974'!$C$2:$C$107,A10,'Prospects 974'!$L$2:$L$107,"Opposition RGPD")
A11: Intérim & recrutement | B11: 2 | C11: =COUNTIF('Prospects 974'!$C$2:$C$107,A11) | D11: =COUNTIFS('Prospects 974'!$C$2:$C$107,A11,'Prospects 974'!$G$2:$G$107,"<>") | E11: =COUNTIFS('Prospects 974'!$C$2:$C$107,A11,'Prospects 974'!$L$2:$L$107,"Contacté")+G11+F11+COUNTIFS('Prospects 974'!$C$2:$C$107,A11,'Prospects 974'!$L$2:$L$107,"Proposition") | F11: =COUNTIFS('Prospects 974'!$C$2:$C$107,A11,'Prospects 974'!$L$2:$L$107,"RDV") | G11: =COUNTIFS('Prospects 974'!$C$2:$C$107,A11,'Prospects 974'!$L$2:$L$107,"Client") | H11: =COUNTIFS('Prospects 974'!$C$2:$C$107,A11,'Prospects 974'!$L$2:$L$107,"Opposition RGPD")
A12: Transport & logistique | B12: 2 | C12: =COUNTIF('Prospects 974'!$C$2:$C$107,A12) | D12: =COUNTIFS('Prospects 974'!$C$2:$C$107,A12,'Prospects 974'!$G$2:$G$107,"<>") | E12: =COUNTIFS('Prospects 974'!$C$2:$C$107,A12,'Prospects 974'!$L$2:$L$107,"Contacté")+G12+F12+COUNTIFS('Prospects 974'!$C$2:$C$107,A12,'Prospects 974'!$L$2:$L$107,"Proposition") | F12: =COUNTIFS('Prospects 974'!$C$2:$C$107,A12,'Prospects 974'!$L$2:$L$107,"RDV") | G12: =COUNTIFS('Prospects 974'!$C$2:$C$107,A12,'Prospects 974'!$L$2:$L$107,"Client") | H12: =COUNTIFS('Prospects 974'!$C$2:$C$107,A12,'Prospects 974'!$L$2:$L$107,"Opposition RGPD")
A13: Agences de voyages | B13: 3 | C13: =COUNTIF('Prospects 974'!$C$2:$C$107,A13) | D13: =COUNTIFS('Prospects 974'!$C$2:$C$107,A13,'Prospects 974'!$G$2:$G$107,"<>") | E13: =COUNTIFS('Prospects 974'!$C$2:$C$107,A13,'Prospects 974'!$L$2:$L$107,"Contacté")+G13+F13+COUNTIFS('Prospects 974'!$C$2:$C$107,A13,'Prospects 974'!$L$2:$L$107,"Proposition") | F13: =COUNTIFS('Prospects 974'!$C$2:$C$107,A13,'Prospects 974'!$L$2:$L$107,"RDV") | G13: =COUNTIFS('Prospects 974'!$C$2:$C$107,A13,'Prospects 974'!$L$2:$L$107,"Client") | H13: =COUNTIFS('Prospects 974'!$C$2:$C$107,A13,'Prospects 974'!$L$2:$L$107,"Opposition RGPD")
A14: Automobile | B14: 3 | C14: =COUNTIF('Prospects 974'!$C$2:$C$107,A14) | D14: =COUNTIFS('Prospects 974'!$C$2:$C$107,A14,'Prospects 974'!$G$2:$G$107,"<>") | E14: =COUNTIFS('Prospects 974'!$C$2:$C$107,A14,'Prospects 974'!$L$2:$L$107,"Contacté")+G14+F14+COUNTIFS('Prospects 974'!$C$2:$C$107,A14,'Prospects 974'!$L$2:$L$107,"Proposition") | F14: =COUNTIFS('Prospects 974'!$C$2:$C$107,A14,'Prospects 974'!$L$2:$L$107,"RDV") | G14: =COUNTIFS('Prospects 974'!$C$2:$C$107,A14,'Prospects 974'!$L$2:$L$107,"Client") | H14: =COUNTIFS('Prospects 974'!$C$2:$C$107,A14,'Prospects 974'!$L$2:$L$107,"Opposition RGPD")
A15: Hôtellerie | B15: 3 | C15: =COUNTIF('Prospects 974'!$C$2:$C$107,A15) | D15: =COUNTIFS('Prospects 974'!$C$2:$C$107,A15,'Prospects 974'!$G$2:$G$107,"<>") | E15: =COUNTIFS('Prospects 974'!$C$2:$C$107,A15,'Prospects 974'!$L$2:$L$107,"Contacté")+G15+F15+COUNTIFS('Prospects 974'!$C$2:$C$107,A15,'Prospects 974'!$L$2:$L$107,"Proposition") | F15: =COUNTIFS('Prospects 974'!$C$2:$C$107,A15,'Prospects 974'!$L$2:$L$107,"RDV") | G15: =COUNTIFS('Prospects 974'!$C$2:$C$107,A15,'Prospects 974'!$L$2:$L$107,"Client") | H15: =COUNTIFS('Prospects 974'!$C$2:$C$107,A15,'Prospects 974'!$L$2:$L$107,"Opposition RGPD")
... A17: BTP | B17: 4 | C17: =COUNTIF('Prospects 974'!$C$2:$C$107,A17) | D17: =COUNTIFS('Prospects 974'!$C$2:$C$107,A17,'Prospects 974'!$G$2:$G$107,"<>") | E17: =COUNTIFS('Prospects 974'!$C$2:$C$107,A17,'Prospects 974'!$L$2:$L$107,"Contacté")+G17+F17+COUNTIFS('Prospects 974'!$C$2:$C$107,A17,'Prospects 974'!$L$2:$L$107,"Proposition") | F17: =COUNTIFS('Prospects 974'!$C$2:$C$107,A17,'Prospects 974'!$L$2:$L$107,"RDV") | G17: =COUNTIFS('Prospects 974'!$C$2:$C$107,A17,'Prospects 974'!$L$2:$L$107,"Client") | H17: =COUNTIFS('Prospects 974'!$C$2:$C$107,A17,'Prospects 974'!$L$2:$L$107,"Opposition RGPD")
A18: TOTAL | C18: =SUM(C4:C17) | D18: =SUM(D4:D17) | E18: =SUM(E4:E17) | F18: =SUM(F4:F17) | G18: =SUM(G4:G17) | H18: =SUM(H4:H17)
A20: « Contactés » = Contacté + Proposition + RDV + Client (toute entreprise déjà touchée).
